Workbook

Sheet Hoja1
A1: Documento | B1: Nombre base de datos | C1: Nivel | D1: MESA_ | E1: Fecha Ingreso | F1: Fecha de retiro | G1: Nombre | H1: Email | I1: Compass | J1: AGENT DATA | K1: Genesys | L1: TUR Training | M1: QA | N1: Feedback | O1: Estado | P1: Vista Dash | Q1: Malla | R1: Evaluation | S1: Directorio Distribuidores MOPAR | T1: Rol Home Office
A2: DICA9809116S6 | B2: aida esperanza diaz cativo | C2: L2 | D2: CAC | E2: =VLOOKUP(A2,Hoja2!A:C,2,FALSE) -> 19/05/2025 | F2: =VLOOKUP(A2,Hoja2!A:C,3,FALSE) -> 45835 | G2: Aida Esperanza Diaz Cativo | H2: 408 | I2: Aida Esperanza Diaz Cativo | K2: Aida Esperanza Diaz Cativo | L2: 218 | M2: 220 | N2: 222 | O2: Inactivo | P2: Inactivo | Q2: 226 | R2: aida.diaz@brm.lat | S2: 396 | T2: 504
A3: ROAA941101N80 | B3: aldo aaron rodriguez arroyo | C3: OTHER | D3: STAFF | E3: =VLOOKUP(A3,Hoja2!A:C,2,FALSE) -> 05/05/2023 | F3: 36893 | G3: Aldo Aaron Rodriguez Arroyo | H3: aldo.rodriguez@brm.lat | I3: Aldo Aaron Rodríguez Arroyo | J3: ALDO AARON RODRIGUEZ ARROYO | K3: 8 | L3: 51 | M3: 69 | N3: 69 | O3: Inactivo | P3: Inactivo | Q3: 155 | R3: aldo.rodriguez@brm.lat | S3: 397 | T3: 505
A4: TOTA970408G2A | B4: alfredo carlos torres trujillo | C4: L2 | D4: PREMIUM | E4: =VLOOKUP(A4,Hoja2!A:C,2,FALSE) -> 45271 | F4: 45980 | G4: Alfredo Carlos Torres Trujillo | H4: 409 | I4: 93 | K4: 99 | L4: 111 | M4: 105 | N4: 105 | O4: Inactivo | P4: Inactivo | Q4: 169 | R4: 210 | S4: 398 | T4: 506
A5: MOAA990219V45 | B5: ana luisa molina aguirre | C5: L2 | D5: CAC | E5: =VLOOKUP(A5,Hoja2!A:C,2,FALSE) -> 22/09/2025 | G5: Ana Luisa Molina Aguirre | H5: ana.molina@brm.lat | I5: Ana Luisa Molina Aguirre | K5: Ana Luisa Molina Aguirre | L5: Ana Molina | M5: Ana Luisa Molina Aguirre | N5: Ana Luisa Molina Aguirre | O5: Activo | P5: Agente | Q5: Ana Luisa Molina Aguirre | R5: ana.molina@brm.lat | S5: 508 | T5: Ana Luis Molina
A6: NERA921105325 | B6: angel alfonso negrete rojas | C6: L2 | D6: CAC | E6: =VLOOKUP(A6,Hoja2!A:C,2,FALSE) -> 12/04/2023 | G6: Angel Alfonso Negrete Rojas | H6: 410 | I6: Angel Alfonso Negrete Rojas | J6: ANGEL ALFONSO NEGRETE ROJAS | K6: Angel Alfonso Negrete Rojas | L6: Angel Negrete | M6: Angel Alfonso Negrete Rojas | N6: Angel Alfonso Negrete Rojas | O6: Activo | P6: Lider | Q6: Angel Alfonso Negrete Rojas | R6: 175 | S6: 399 | T6: Angel Alfonso Negrete Rojas
A7: 1015475044 | B7: angela natalia escobar castro | C7: OTHER | D7: STAFF | E7: 45538 | G7: Angela Natalia Escobar Castro | H7: angela.escobar@brm.com.co | I7: 290 | K7: 291 | L7: 292 | M7: 293 | N7: 294 | O7: Activo | P7: Data | Q7: 296 | R7: angela.escobar@brm.com.co | S7: 400 | T7: 507
A8: ROCA880719R6A | B8: ariel rosas colin | C8: L2 | D8: CAC | E8: =VLOOKUP(A8,Hoja2!A:C,2,FALSE) -> 24/03/2025 | G8: Ariel Rosas Colin | H8: 411 | I8: Ariel Rosas Colin | K8: Ariel Rosas Colin | L8: Ariel Rosas Colin | M8: Ariel Rosas Colin | N8: Ariel Rosas Colin | O8: Activo | P8: Agente | Q8: Ariel Rosas Colin | R8: ariel.rosas@brm.lat | S8: 401 | T8: Ariel Rosas Colin
A9: MICA030425FXA | B9: arturo jovan michel caballero | C9: L2 | D9: PREMIUM | E9: =VLOOKUP(A9,Hoja2!A:C,2,FALSE) -> 16/07/2025 | F9: =VLOOKUP(A9,Hoja2!A:C,3,FALSE) -> 45945 | G9: Arturo Jovan Michel Caballero | H9: arturo.michel@brm.lat | I9: Arturo Caballero | J9: 475 | K9: Arturo Caballero | L9: 477 | M9: Arturo Caballero | N9: 479 | O9: Inactivo | P9: Inactivo | Q9: Arturo Jovan Michel Caballero | R9: 482 | S9: 483 | T9: Arturo Jovan Michel
A10: HELB930528PQ6 | B10: bernardo herrera lucas | C10: BIL | D10: WARRANTY | E10: =VLOOKUP(A10,Hoja2!A:C,2,FALSE) -> 23/04/2025 | G10: Bernardo Herrera Lucas | H10: 412 | I10: Bernardo Herrera Lucas | J10: BERNARDO HERRERA LUCAS | K10: 9 | L10: 52 | M10: Bernardo Herrera Lucas | N10: Bernardo Herrera Lucas | O10: Activo | P10: Agente | Q10: Bernardo Herrera Lucas | R10: 176 | S10: 402 | T10: Bernardo Herrera Lucas
A11: PECB0204186B4 | B11: beverly perez carmona | C11: L2 | D11: CAC | E11: =VLOOKUP(A11,Hoja2!A:C,2,FALSE) -> 20/05/2024 | F11: =VLOOKUP(A11,Hoja2!A:C,3,FALSE) -> 45945 | G11: Beverly Perez Carmona | H11: 413 | I11: Beverly Perez | J11: BEVERLY PEREZ CARMONA | K11: Beverly Perez Carmona | L11: Beberly Perez | M11: Beverly Pérez Carmona | N11: Beverly Pérez Carmona | O11: Inactivo | P11: Inactivo | Q11: Beverly Pérez Carmona | R11: beverly.perez@brm.lat | S11: 403 | T11: Beverly Perez Carmona
A12: HEVB960903C82 | B12: brenda aylin hernandez ventura | C12: L2 | D12: CAC | E12: =VLOOKUP(A12,Hoja2!A:C,2,FALSE) -> 15/01/2024 | G12: Brenda Aylin Hernandez Ventura | H12: 414 | I12: Brenda Aylin Hernandez Ventura | J12: BRENDA AYLIN HERNANDEZ VENTURA | K12: Branda Aylin Hernandez Ventura | L12: Brenda Hernandez | M12: Brenda Aylin Hernández Ventura | N12: Brenda Aylin Hernández Ventura | O12: Activo | P12: Agente | Q12: Brenda Aylin Hernández Ventura | R12: 177 | S12: 404 | T12: Brenda Aylin Hernández Ventura
A13: MOMB940920E68 | B13: brenda leticia morales munoz | C13: L2 | D13: FLEET | E13: =VLOOKUP(A13,Hoja2!A:C,2,FALSE) -> 12/04/2023 | G13: Brenda Leticia Morales Munoz | H13: 415 | I13: 23 | K13: Brenda Leticia Morales Muñoz | L13: 65 | M13: Brenda Leticia Morales Muñoz | N13: Brenda Leticia Morales Muñoz | O13: Activo | P13: Agente | Q13: Brenda Leticia Morales Muñoz | R13: 195 | S13: BRENDA | T13: Brenda Leticia Morales Muñoz
A14: COMC900329TX1 | B14: carlos francisco contreras moreno | C14: OTHER | D14: PROGRAM MANAGER | E14: =VLOOKUP(A14,Hoja2!A:C,2,FALSE) -> 26/06/2023 | G14: Carlos Francisco Contreras Moreno | H14: carlos.contreras@brm.com.co | I14: 227 | K14: 236 | L14: 245 | M14: 254 | N14: 263 | O14: Activo | P14: Manager | Q14: 281 | R14: carlos.contreras@brm.com.co | S14: 406 | T14: 508
A15: NACC9505286W9 | B15: carolina nava cruz | C15: PEPSICO | D15: PEPSICO | E15: =VLOOKUP(A15,Hoja2!A:C,2,FALSE) -> 23/12/2021 | G15: Carolina Nava Cruz | H15: carolina.nava@brm.com.co | I15: 228 | K15: 237 | L15: 246 | M15: 255 | N15: 264 | O15: Activo | P15: Agente | Q15: 282 | R15: carolina.nava@brm.com.co | S15: 345 | T15: 509
A16: OUMC940127JZ8 | B16: christian gerardo ortuno mayen | C16: L2 | D16: PREMIUM | E16: =VLOOKUP(A16,Hoja2!A:C,2,FALSE) -> 11/12/2023 | F16: =VLOOKUP(A16,Hoja2!A:C,3,FALSE) -> 45888 | G16: Christian Gerardo Ortuno Mayen | H16: christian.ortuno@brm.lat | I16: Christian Ortuno | K16: 45 | L16: Christian Ortuño | M16: Christian Ortuno | N16: 87 | O16: Inactivo | P16: Inactivo | Q16: Christian Gerardo Ortuno Mayen | R16: christian.ortuno@brm.lat | S16: 346 | T16: 510
A17: LAMC960519QR8 | B17: citlali lara morales | C17: L2 | D17: CAC | E17: =VLOOKUP(A17,Hoja2!A:C,2,FALSE) -> 11/12/2023 | F17: =VLOOKUP(A17,Hoja2!A:C,3,FALSE) -> 45708 | G17: Citlali Lara Morales | H17: 416 | I17: Citlali Lara | K17: 46 | L17: Citlali Lara | M17: Citlali Lara | N17: 88 | O17: Inactivo | P17: Inactivo | Q17: Citali Lara Morales | R17: 205 | S17: 347 | T17: 511
A18: MELD991221AV5 | B18: daniel axel mejia lopez | C18: OTHER | D18: STAFF | E18: =VLOOKUP(A18,Hoja2!A:C,2,FALSE) -> 04/05/2023 | G18: Daniel Axel Mejia Lopez | H18: daniel.mejia@brm.lat | I18: Daniel Mejia | J18: DANIEL MEJIA | K18: 10 | L18: 53 | M18: 71 | N18: 71 | O18: Activo | P18: Agente | Q18: 156 | R18: daniel.mejia@brm.com.co | S18: 348 | T18: Daniel Mejía
A19: SAVD670108S4A | B19: Daniel Sanchez Vallejo | C19: BIL | D19: PDC | E19: =VLOOKUP(A19,Hoja2!A:C,2,FALSE) -> 08/05/2023 | G19: Daniel Sanchez Vallejo | H19: 417 | I19: 308 | K19: 313 | L19: 318 | M19: 323 | N19: 328 | O19: Activo | P19: Agente | Q19: Daniel Sanchez Vallejo | R19: 343 | S19: 349 | T19: Daniel Sánchez Vallejo
A20: VIGD960720IM4 | B20: daniel villanueva gonzalez | C20: OTHER | D20: STAFF | E20: =VLOOKUP(A20,Hoja2!A:C,2,FALSE) -> 01/08/2023 | F20: =VLOOKUP(A20,Hoja2!A:C,3,FALSE) -> 45719 | G20: Daniel Villanueva Gonzalez | H20: 418 | I20: Daniel Villanueva Gonzalez | J20: DANIEL VILLANUEVA GONZALEZ | K20: 11 | L20: 54 | M20: 72 | N20: 72 | O20: Inactivo | P20: Inactivo | Q20: 157 | R20: 179 | S20: 350 | T20: 512
A21: GOCD990717AS3 | B21: dante abraham gonzalez carcamo | C21: L2 | D21: PREMIUM | E21: =VLOOKUP(A21,Hoja2!A:C,2,FALSE) -> 20/10/2025 | G21: Dante Abraham Gonzalez Carcamo | H21: dante.carcamo@brm.lat | I21: 555 | J21: 556 | K21: Dante González | L21: 558 | M21: 559 | N21: 560 | O21: Activo | P21: Agente | Q21: 562 | R21: 563 | S21: 564 | T21: 566
A22: CERD7807235L2 | B22: david daniel cedillo rivera | C22: BIL | D22: CAC | E22: =VLOOKUP(A22,Hoja2!A:C,2,FALSE) -> 01/05/2023 | G22: David Daniel Cedillo Rivera | H22: david.cedillo@brm.lat | I22: David Cedillo | J22: DAVID DANIEL CEDILLO RIVERA | K22: David Daniel Cedillo Rivera | L22: 55 | M22: 73 | N22: 73 | O22: Activo | P22: Lider | Q22: David Daniel Cedillo Rivera | R22: 180 | S22: 351 | T22: David Daniel Cedillo Rivera
A23: CADD840914Q56 | B23: david ricardo camarena diaz | C23: L2 | D23: PREMIUM | E23: =VLOOKUP(A23,Hoja2!A:C,2,FALSE) -> 11/12/2023 | G23: David Ricardo Camarena Diaz | H23: david.camarena@brm.lat | I23: David Camarena | K23: David Camarena | L23: David Camarena | M23: David Camarena | N23: 90 | O23: Activo | P23: Agente | Q23: David Ricardo Camarena Díaz | R23: david.camarena@brm.lat | S23: 352 | T23: David Ricardo Camarena Díaz
A24: SILD9507304HA | B24: diego silva lerista | C24: L2 | D24: PREMIUM | E24: =VLOOKUP(A24,Hoja2!A:C,2,FALSE) -> 16/07/2025 | G24: Diego Silva Lerista | H24: diego.silva@brm.lat | I24: Diego Lerista | J24: 485 | K24: Diego Lerista | L24: 487 | M24: Diego Lerista | N24: 489 | O24: Activo | P24: Agente | Q24: Diego Silva Lerista | R24: 492 | S24: 493 | T24: Diego Lerista
A25: AAME930716V5A | B25: elizabeth tania anaya martinez | C25: L2 | D25: FLEET | E25: =VLOOKUP(A25,Hoja2!A:C,2,FALSE) -> 01/09/2023 | G25: Elizabeth Tania Anaya Martinez | H25: 419 | I25: Elizabeth Tania Anaya Martinez | J25: ELIZABETH TANIA ANAYA MARTINEZ | K25: Elizabeth Tania Anaya Martinez | L25: Elizabeth Anaya | M25: Elizabeth Tania Anaya Martínez | N25: Elizabeth Tania Anaya Martínez | O25: Activo | P25: Agente | Q25: Elizabeth Tania Anaya Martínez | R25: 181 | S25: ELIZABETH | T25: Elizabeth Tania Anaya Martinez
A26: RODE9405272WA | B26: emmy zenyace rodriguez dominguez | C26: OTHER | D26: STAFF | E26: =VLOOKUP(A26,Hoja2!A:C,2,FALSE) -> 11/12/2023 | G26: Emmy Zenyace Rodriguez Dominguez | H26: 420 | I26: Emmy Rodriguez | K26: 44 | L26: Emmy Rodriguez | M26: Emmy Rodriguez | N26: 86 | O26: Activo | P26: Agente | Q26: Emmy Zenyace Rodríguez Domínguez | R26: 203 | S26: 353 | T26: Erika Jacqueline Manzanarez Sotelo
A27: MASE970408PN6 | B27: erika jacqueline manzanarez sotelo | C27: L2 | D27: FLEET | E27: =VLOOKUP(A27,Hoja2!A:C,2,FALSE) -> 06/07/2023 | G27: Erika Jacqueline Manzanarez Sotelo | H27: 421 | I27: Ericka Jacqueline Manzanarez Sotelo | J27: ERIKA JACQUELINE MANZANAREZ SOTELO | K27: Ericka Jaqueline Manzanarez Sotelo | L27: 56 | M27: Erika Jacqueline Manzanarez Sotelo | N27: Erika Jacqueline Manzanarez Sotelo | O27: Activo | P27: Agente | Q27: Erika Jacqueline Manzanarez Sotelo | R27: 182 | S27: ERIKA | T27: Erika Rodríguez Pérez
A28: ROPE750902RE8 | B28: erika rodriguez perez | C28: L2 | D28: PREMIUM | E28: =VLOOKUP(A28,Hoja2!A:C,2,FALSE) -> 12/12/2023 | G28: Erika Rodriguez Perez | H28: erika.rodriguez@brm.lat | I28: Erika Rodriguez | K28: Erika Rodriguez | L28: Erika Rodriguez | M28: Erika Rodriguez | N28: 89 | O28: Activo | P28: Agente | Q28: Erika Rodríguez Pérez | R28: erika.rodriguez@brm.lat | S28: 354 | T28: 513
A29: HEFE932203E43 | B29: Evelyn Andrea Hernandez Flores | C29: L2 | D29: CAC | E29: =VLOOKUP(A29,Hoja2!A:C,2,FALSE) -> 05/02/2025 | G29: Evelyn Andrea Hernandez Flores | H29: 422 | I29: Evelyn Andrea Hernandez Flores | K29: Evelyn Andrea Hernandez Flores | L29: Evelyn Hernandez | M29: Evelyn Andrea Hernandez Flores | N29: Evelyn Andrea Hernandez Flores | O29: Activo | P29: Agente | Q29: Evelyn Andrea Hernandez Flores | R29: evelyn.hernandez@brm.lat | S29: 355 | T29: Evelyn Andrea Hernandez
A30: GUAG9805103UA | B30: gabriela ahuic guerrero acosta | C30: L2 | D30: PREMIUM | E30: =VLOOKUP(A30,Hoja2!A:C,2,FALSE) -> 04/03/2024 | G30: Gabriela Ahuic Guerrero Acosta | H30: gabriela.guerrero@brm.lat | I30: Gabriela Guerrero | K30: Gabriela Guerrero | L30: 112 | M30: Gabriela Guerrero | N30: 106 | O30: Activo | P30: Agente | Q30: Gabriela Ahuic Guerrero Acosta | R30: gabriela.guerrero@brm.lat | S30: 356 | T30: Gabriela Ahuic Guerrero Acosta
A31: HEBG9812126W4 | B31: guadalupe itzel hernández baza | C31: L2 | D31: PREMIUM | E31: =VLOOKUP(A31,Hoja2!A:C,2,FALSE) -> 02/10/2024 | G31: Guadalupe Itzel Hernández Baza | H31: guadalupe.hernandez@brm.lat | I31: Guadalupe Hernandez Baza | K31: Guadalupe Hernandez Baza | L31: Guadalupe Baza | M31: Guadalupe Hernandez | N31: 91 | O31: Activo | P31: Agente | Q31: Guadalupe Itzel Hernández baza | R31: guadalupe.hernandez@brm.lat | S31: 357 | T31: Guadalupe Hernandez Baza
A32: 1 | B32: Hot Alert Mexico Vehicle | C32: OTHER | D32: OTHER | E32: 36892 | F32: 36893 | G32: Hot Alert Mexico Vehicle | H32: 423 | I32: Hot Alert Mexico Vehicle | K32: 13 | L32: 57 | M32: 74 | N32: 74 | O32: Inactivo | P32: Inactivo | Q32: 158 | R32: 183 | S32: 358 | T32: 514
A33: COZI930808G27 | B33: ignacio tonatiuh correa zamora | C33: L2 | D33: CAC | E33: =VLOOKUP(A33,Hoja2!A:C,2,FALSE) -> 03/10/2023 | F33: =VLOOKUP(A33,Hoja2!A:C,3,FALSE) -> 45844 | G33: Ignacio Tonatiuh Correa Zamora | H33: 424 | I33: Ignacio Zamora | K33: 42 | L33: Ignacion Correa | M33: Ignacio Zamora | N33: 84 | O33: Inactivo | P33: Inactivo | Q33: 167 | R33: 201 | S33: 359 | T33: 515
A34: ROMI870125PR2 | B34: itzel lucia rodriguez medellin | C34: L2 | D34: CAC | E34: =VLOOKUP(A34,Hoja2!A:C,2,FALSE) -> 19/05/2025 | G34: Itzel Lucia Rodriguez Medellin | H34: 425 | I34: Itzel Rodriguez Medellin | K34: Itzel Rodriguez Medellin | L34: 217 | M34: Itzel Rodriguez Medellín | N34: 221 | O34: Activo | P34: Agente | Q34: Itzel Lucia Rodriguez Medellin | R34: itzel.rodriguez@brm.lat | S34: 360 | T34: Itzel Rodriguez
A35: TOHI950502JJ9 | B35: itzel torres herrera | C35: L2 | D35: FLEET | E35: =VLOOKUP(A35,Hoja2!A:C,2,FALSE) -> 12/04/2023 | G35: Itzel Torres Herrera | H35: 426 | I35: 25 | K35: Itzel Torres Herrera | L35: 67 | M35: Itzel Torres Herrera | N35: Itzel Torres Herrera | O35: Activo | P35: Agente | Q35: Itzel Torres Herrera | R35: 197 | S35: ITZEL | T35: Itzel Torres Herrera
A36: JIRJ0305303Y2 | B36: jacqueline jimeno rosales | C36: L2 | D36: CAC | E36: =VLOOKUP(A36,Hoja2!A:C,2,FALSE) -> 06/07/2023 | F36: =VLOOKUP(A36,Hoja2!A:C,3,FALSE) -> 45708 | G36: Jacqueline Jimeno Rosales | H36: 427 | I36: Jacqueline Jimeno | K36: 40 | L36: Jaqueline Jimeno | M36: Jacqueline Jimeno | N36: 82 | O36: Inactivo | P36: Inactivo | Q36: Jacqueline Jimeno Rosales | R36: 199 | S36: 361 | T36: 516
A37: MAGJ940620SEA | B37: javier martinez garcia | C37: PEPSICO | D37: PEPSICO | E37: =VLOOKUP(A37,Hoja2!A:C,2,FALSE) -> 23/12/2021 | G37: Javier Martinez Garcia | H37: javier.martinez@brm.com.co | I37: 229 | K37: 238 | L37: 247 | M37: 256 | N37: 265 | O37: Activo | P37: Agente | Q37: 283 | R37: javier.martinez@brm.com.co | S37: 362 | T37: 517
A38: 2 | B38: Jennifer Trudell | C38: OTHER | D38: OTHER | E38: 36892 | F38: 36893 | G38: Jennifer Trudell | H38: 428 | I38: Jennifer Trudell | K38: 14 | L38: 58 | M38: 75 | N38: 75 | O38: Inactivo | P38: Inactivo | Q38: 159 | R38: 184 | S38: 363 | T38: 518
A39: BOPJ921127PQ0 | B39: jessica lorena bonces pardo | C39: PEPSICO | D39: PEPSICO | E39: 44348 | G39: Jessica Lorena Bonces Pardo | H39: jessica.bonces@brm.com.co | I39: 230 | K39: 239 | L39: 248 | M39: 257 | N39: 266 | O39: Activo | P39: Lider | Q39: 284 | R39: jessica.bonces@brm.com.co | S39: 364 | T39: 519
A40: RUCJ021118JT2 | B40: jesus armando ruiz cruz | C40: L2 | D40: FLEET | E40: 45936 | G40: Jesus Armando Ruiz Cruz | H40: jesus.ruiz@brm.lat | I40: 504 | K40: Jesus Ruiz | L40: 505 | M40: Jesus Armando Ruiz Cruz | N40: Jesus Armando Ruiz Cruz | O40: Activo | P40: Agente | Q40: Jesus Armando Ruiz Cruz | R40: jesus.ruiz@brm.lat | S40: 509 | T40: Jesús Armando Ruiz
...

Sheet Hoja2
A1: RFC | B1: Fecha de contratacion | C1: Fecha de retiro
A2: PAMD9909214N2 | B2: 45026 | C2: 45057
A3: DICA9609116S6 | B3: 44714 | C3: 45289
A4: HUCL940609PB1 | B4: 44722 | C4: 45291
A5: LEMG7409013B7 | B5: 45008 | C5: 45387
A6: RETS9412067Q3 | B6: 44556 | C6: 45443
A7: AUFJ951026IQ6 | B7: 45028 | C7: 45042
A8: SIMJ890303523 | B8: 45028 | C8: 45042
A9: GAHL611052H4 | B9: 45034 | C9: 45076
A10: LEMB8807042U1 | B10: 45028 | C10: 45083
A11: SOPJ941004890 | B11: 45028 | C11: 45096
A12: EISL980413SC8 | B12: 45066 | C12: 45097
A13: EDOLE830703Q17 | B13: 45083 | C13: 45097
... A60: FEGR0106237E1 | B60: 45212 | C60: 45525
A61: MABL9008255N0 | B61: 45544 | C61: #N/A
A62: AIHE910423HDFRRR09 | B62: 44291 | C62: #N/A
A63: EUPR941121HDFSRB08 | B63: 44445 | C63: #N/A
A64: FANA871207MDFLYD01 | B64: 44445 | C64: #N/A
A65: GOMN891221MDFMYZ03 | B65: 44348 | C65: #N/A
A66: GOMV910123HDFNNC08 | B66: 44445 | C66: #N/A
A67: LANT900402MDFNCN07 | B67: 44452 | C67: #N/A
A68: LIBS830810MVZMLR02 | B68: 44258 | C68: #N/A
A69: LONE871226MDFPNR05 | B69: 44452 | C69: #N/A
A70: LOSA980629HDFPNL04 | B70: 44452 | C70: #N/A
A71: CALB00012HDFRMRA4 | B71: 44445 | C71: #N/A
A72: TOTA970408G2A | B72: 45271 | C72: #N/A
A73: AOGE840609TM0 | B73: 45621 | C73: #N/A
A74: MAMM9508035T9 | B74: 02/05/2022 | C74: 45670
A75: VIGD960720IM4 | B75: 01/08/2023 | C75: 45719
A76: SAAY841006C99 | B76: 03/03/2025 | C76: 45785
A77: ZEVM961222FRA | B77: 12/04/2023 | C77: 45758
A78: GOLJ9503038V9 | B78: 07/04/2025 | C78: 45785
A79: ZACM970618N37 | B79: 11/08/2025 | C79: Null
A80: SAMP9601121P8 | B80: 01/05/2023 | C80: 45820
A81: AOBJ730421DQ9 | B81: 01/06/2021 | C81: Null
A82: AERP8312122CA | B82: 11/10/2021 | C82: Null
A83: MAGJ940620SEA | B83: 23/12/2021 | C83: Null
A84: MAHK9112058E6 | B84: 20/06/2022 | C84: Null
A85: BEGN940822DRA | B85: 01/09/2022 | C85: Null
A86: MACG880903UY4 | B86: 24/01/2023 | C86: 45900
...
